Workbook

Sheet Lease Comparison
B2: Lease NPV Comparison — Building Owner
B3: You own the building. Rent = your income. Investment = your cost to prepare the space.
B5: SHARED ASSUMPTIONS
B7: Discount Rate (Annual) | C7: 0.08 | E7: Total Analysis Months | F7: =C9*12 -> 60
B8: Monthly Discount Rate | C8: =(1+C7)^(1/12)-1 -> 0.0064340301
B9: Analysis Horizon (Years) | C9: =MAX(C14,F14) -> 5
B11: LEASE A — INPUTS | E11: LEASE B — INPUTS
B13: Monthly Rent (Income to You) | C13: 4500 | E13: Monthly Rent (Income to You) | F13: 4800
B14: Lease Term (Years) | C14: 1 | E14: Lease Term (Years) | F14: 5
B15: Your Upfront Investment | C15: 0 | E15: Your Upfront Investment | F15: 35000
B16: Annual Rent Escalation | C16: 0.03 | E16: Annual Rent Escalation | F16: 0.03
B17: Vacancy Between Leases (Months) | C17: 3 | E17: Vacancy Between Leases (Months) | F17: 3
B19: Lease Cycle (Lease + Vacancy) | C19: =C14*12+C17 -> 15 | E19: Lease Cycle (Lease + Vacancy) | F19: =F14*12+F17 -> 63
B20: Net NPV over Full Horizon | C20: ='Cash Flows'!E67 -> 190003.81 | E20: Net NPV over Full Horizon | F20: ='Cash Flows'!I67 -> 216881.75
B21: Net NPV per Month | C21: =IF(F7>0,C20/F7,0) -> 3166.7302 | E21: Net NPV per Month | F21: =IF(F7>0,F20/F7,0) -> 3614.6958
B23: COMPARISON — OVER SAME TIME HORIZON
B25: Metric | C25: Lease A | E25: Lease B | F25: A vs B
B26: Monthly Rent | C26: =C13 -> 4500 | E26: =F13 -> 4800 | F26: =C13-F13 -> -300
B27: Lease Term (Years) | C27: =C14 -> 1 | E27: =F14 -> 5 | F27: =C14-F14 -> -4
B28: Your Upfront Investment | C28: =C15 -> 0 | E28: =F15 -> 35000 | F28: =C15-F15 -> -35000
B29: Vacancy Between Leases (Mo) | C29: =C17 -> 3 | E29: =F17 -> 3 | F29: =C17-F17 -> 0
B30: Net NPV over Horizon | C30: =C20 -> 190003.81 | E30: =F20 -> 216881.75 | F30: =C20-F20 -> -26877.935
B31: Net NPV per Month | C31: =C21 -> 3166.7302 | E31: =F21 -> 3614.6958 | F31: =C21-F21 -> -447.96559
B33: =IF(C21>F21,"RECOMMENDATION: Lease A earns $"&TEXT(C21-F21,"#,##0")&" more/month over "&TEXT(C9,"0")&" years","RECOMMENDATION: Lease B earns $"&TEXT(F21-C21,"#,##0")&" more/month over "&TEXT(C9,"0")&" years") -> RECOMMENDATION: Lease B earns $448 more/month over 5 years
B34: Both leases evaluated over the same horizon. Shorter leases cycle through lease + vacancy periods.

Sheet Cash Flows
B2: Monthly Cash Flow Detail (Over Full Analysis Horizon)
B4: LEASE A — RENT INCOME (with vacancy cycling) | G4: LEASE B — RENT INCOME (with vacancy cycling)
B5: Month | C5: Rent Income | D5: Discount Factor | E5: PV of Income | G5: Rent Income | H5: Discount Factor | I5: PV of Income
B6: 1 | C6: =IF(B6<='Lease Comparison'!F7,IF(MOD(B6-1,'Lease Comparison'!C19)<'Lease Comparison'!C14*12,'Lease Comparison'!C13*(1+'Lease Comparison'!C16)^INT((B6-1)/12),0),0) -> 4500 | D6: =IF(B6<='Lease Comparison'!F7,1/(1+'Lease Comparison'!C8)^B6,0) -> 0.9936071 | E6: =C6*D6 -> 4471.232 | G6: =IF(B6<='Lease Comparison'!F7,IF(MOD(B6-1,'Lease Comparison'!F19)<'Lease Comparison'!F14*12,'Lease Comparison'!F13*(1+'Lease Comparison'!F16)^INT((B6-1)/12),0),0) -> 4800 | H6: =IF(B6<='Lease Comparison'!F7,1/(1+'Lease Comparison'!C8)^B6,0) -> 0.9936071 | I6: =G6*H6 -> 4769.3141
B7: 2 | C7: =IF(B7<='Lease Comparison'!F7,IF(MOD(B7-1,'Lease Comparison'!C19)<'Lease Comparison'!C14*12,'Lease Comparison'!C13*(1+'Lease Comparison'!C16)^INT((B7-1)/12),0),0) -> 4500 | D7: =IF(B7<='Lease Comparison'!F7,1/(1+'Lease Comparison'!C8)^B7,0) -> 0.98725507 | E7: =C7*D7 -> 4442.6478 | G7: =IF(B7<='Lease Comparison'!F7,IF(MOD(B7-1,'Lease Comparison'!F19)<'Lease Comparison'!F14*12,'Lease Comparison'!F13*(1+'Lease Comparison'!F16)^INT((B7-1)/12),0),0) -> 4800 | H7: =IF(B7<='Lease Comparison'!F7,1/(1+'Lease Comparison'!C8)^B7,0) -> 0.98725507 | I7: =G7*H7 -> 4738.8244
B8: 3 | C8: =IF(B8<='Lease Comparison'!F7,IF(MOD(B8-1,'Lease Comparison'!C19)<'Lease Comparison'!C14*12,'Lease Comparison'!C13*(1+'Lease Comparison'!C16)^INT((B8-1)/12),0),0) -> 4500 | D8: =IF(B8<='Lease Comparison'!F7,1/(1+'Lease Comparison'!C8)^B8,0) -> 0.98094365 | E8: =C8*D8 -> 4414.2464 | G8: =IF(B8<='Lease Comparison'!F7,IF(MOD(B8-1,'Lease Comparison'!F19)<'Lease Comparison'!F14*12,'Lease Comparison'!F13*(1+'Lease Comparison'!F16)^INT((B8-1)/12),0),0) -> 4800 | H8: =IF(B8<='Lease Comparison'!F7,1/(1+'Lease Comparison'!C8)^B8,0) -> 0.98094365 | I8: =G8*H8 -> 4708.5295
B9: 4 | C9: =IF(B9<='Lease Comparison'!F7,IF(MOD(B9-1,'Lease Comparison'!C19)<'Lease Comparison'!C14*12,'Lease Comparison'!C13*(1+'Lease Comparison'!C16)^INT((B9-1)/12),0),0) -> 4500 | D9: =IF(B9<='Lease Comparison'!F7,1/(1+'Lease Comparison'!C8)^B9,0) -> 0.97467258 | E9: =C9*D9 -> 4386.0266 | G9: =IF(B9<='Lease Comparison'!F7,IF(MOD(B9-1,'Lease Comparison'!F19)<'Lease Comparison'!F14*12,'Lease Comparison'!F13*(1+'Lease Comparison'!F16)^INT((B9-1)/12),0),0) -> 4800 | H9: =IF(B9<='Lease Comparison'!F7,1/(1+'Lease Comparison'!C8)^B9,0) -> 0.97467258 | I9: =G9*H9 -> 4678.4284
B10: 5 | C10: =IF(B10<='Lease Comparison'!F7,IF(MOD(B10-1,'Lease Comparison'!C19)<'Lease Comparison'!C14*12,'Lease Comparison'!C13*(1+'Lease Comparison'!C16)^INT((B10-1)/12),0),0) -> 4500 | D10: =IF(B10<='Lease Comparison'!F7,1/(1+'Lease Comparison'!C8)^B10,0) -> 0.9684416 | E10: =C10*D10 -> 4357.9872 | G10: =IF(B10<='Lease Comparison'!F7,IF(MOD(B10-1,'Lease Comparison'!F19)<'Lease Comparison'!F14*12,'Lease Comparison'!F13*(1+'Lease Comparison'!F16)^INT((B10-1)/12),0),0) -> 4800 | H10: =IF(B10<='Lease Comparison'!F7,1/(1+'Lease Comparison'!C8)^B10,0) -> 0.9684416 | I10: =G10*H10 -> 4648.5197
B11: 6 | C11: =IF(B11<='Lease Comparison'!F7,IF(MOD(B11-1,'Lease Comparison'!C19)<'Lease Comparison'!C14*12,'Lease Comparison'!C13*(1+'Lease Comparison'!C16)^INT((B11-1)/12),0),0) -> 4500 | D11: =IF(B11<='Lease Comparison'!F7,1/(1+'Lease Comparison'!C8)^B11,0) -> 0.96225045 | E11: =C11*D11 -> 4330.127 | G11: =IF(B11<='Lease Comparison'!F7,IF(MOD(B11-1,'Lease Comparison'!F19)<'Lease Comparison'!F14*12,'Lease Comparison'!F13*(1+'Lease Comparison'!F16)^INT((B11-1)/12),0),0) -> 4800 | H11: =IF(B11<='Lease Comparison'!F7,1/(1+'Lease Comparison'!C8)^B11,0) -> 0.96225045 | I11: =G11*H11 -> 4618.8022
B12: 7 | C12: =IF(B12<='Lease Comparison'!F7,IF(MOD(B12-1,'Lease Comparison'!C19)<'Lease Comparison'!C14*12,'Lease Comparison'!C13*(1+'Lease Comparison'!C16)^INT((B12-1)/12),0),0) -> 4500 | D12: =IF(B12<='Lease Comparison'!F7,1/(1+'Lease Comparison'!C8)^B12,0) -> 0.95609888 | E12: =C12*D12 -> 4302.445 | G12: =IF(B12<='Lease Comparison'!F7,IF(MOD(B12-1,'Lease Comparison'!F19)<'Lease Comparison'!F14*12,'Lease Comparison'!F13*(1+'Lease Comparison'!F16)^INT((B12-1)/12),0),0) -> 4800 | H12: =IF(B12<='Lease Comparison'!F7,1/(1+'Lease Comparison'!C8)^B12,0) -> 0.95609888 | I12: =G12*H12 -> 4589.2746
B13: 8 | C13: =IF(B13<='Lease Comparison'!F7,IF(MOD(B13-1,'Lease Comparison'!C19)<'Lease Comparison'!C14*12,'Lease Comparison'!C13*(1+'Lease Comparison'!C16)^INT((B13-1)/12),0),0) -> 4500 | D13: =IF(B13<='Lease Comparison'!F7,1/(1+'Lease Comparison'!C8)^B13,0) -> 0.94998664 | E13: =C13*D13 -> 4274.9399 | G13: =IF(B13<='Lease Comparison'!F7,IF(MOD(B13-1,'Lease Comparison'!F19)<'Lease Comparison'!F14*12,'Lease Comparison'!F13*(1+'Lease Comparison'!F16)^INT((B13-1)/12),0),0) -> 4800 | H13: =IF(B13<='Lease Comparison'!F7,1/(1+'Lease Comparison'!C8)^B13,0) -> 0.94998664 | I13: =G13*H13 -> 4559.9359
B14: 9 | C14: =IF(B14<='Lease Comparison'!F7,IF(MOD(B14-1,'Lease Comparison'!C19)<'Lease Comparison'!C14*12,'Lease Comparison'!C13*(1+'Lease Comparison'!C16)^INT((B14-1)/12),0),0) -> 4500 | D14: =IF(B14<='Lease Comparison'!F7,1/(1+'Lease Comparison'!C8)^B14,0) -> 0.94391347 | E14: =C14*D14 -> 4247.6106 | G14: =IF(B14<='Lease Comparison'!F7,IF(MOD(B14-1,'Lease Comparison'!F19)<'Lease Comparison'!F14*12,'Lease Comparison'!F13*(1+'Lease Comparison'!F16)^INT((B14-1)/12),0),0) -> 4800 | H14: =IF(B14<='Lease Comparison'!F7,1/(1+'Lease Comparison'!C8)^B14,0) -> 0.94391347 | I14: =G14*H14 -> 4530.7847
B15: 10 | C15: =IF(B15<='Lease Comparison'!F7,IF(MOD(B15-1,'Lease Comparison'!C19)<'Lease Comparison'!C14*12,'Lease Comparison'!C13*(1+'Lease Comparison'!C16)^INT((B15-1)/12),0),0) -> 4500 | D15: =IF(B15<='Lease Comparison'!F7,1/(1+'Lease Comparison'!C8)^B15,0) -> 0.93787913 | E15: =C15*D15 -> 4220.4561 | G15: =IF(B15<='Lease Comparison'!F7,IF(MOD(B15-1,'Lease Comparison'!F19)<'Lease Comparison'!F14*12,'Lease Comparison'!F13*(1+'Lease Comparison'!F16)^INT((B15-1)/12),0),0) -> 4800 | H15: =IF(B15<='Lease Comparison'!F7,1/(1+'Lease Comparison'!C8)^B15,0) -> 0.93787913 | I15: =G15*H15 -> 4501.8198
B16: 11 | C16: =IF(B16<='Lease Comparison'!F7,IF(MOD(B16-1,'Lease Comparison'!C19)<'Lease Comparison'!C14*12,'Lease Comparison'!C13*(1+'Lease Comparison'!C16)^INT((B16-1)/12),0),0) -> 4500 | D16: =IF(B16<='Lease Comparison'!F7,1/(1+'Lease Comparison'!C8)^B16,0) -> 0.93188336 | E16: =C16*D16 -> 4193.4751 | G16: =IF(B16<='Lease Comparison'!F7,IF(MOD(B16-1,'Lease Comparison'!F19)<'Lease Comparison'!F14*12,'Lease Comparison'!F13*(1+'Lease Comparison'!F16)^INT((B16-1)/12),0),0) -> 4800 | H16: =IF(B16<='Lease Comparison'!F7,1/(1+'Lease Comparison'!C8)^B16,0) -> 0.93188336 | I16: =G16*H16 -> 4473.0401
B17: 12 | C17: =IF(B17<='Lease Comparison'!F7,IF(MOD(B17-1,'Lease Comparison'!C19)<'Lease Comparison'!C14*12,'Lease Comparison'!C13*(1+'Lease Comparison'!C16)^INT((B17-1)/12),0),0) -> 4500 | D17: =IF(B17<='Lease Comparison'!F7,1/(1+'Lease Comparison'!C8)^B17,0) -> 0.92592593 | E17: =C17*D17 -> 4166.6667 | G17: =IF(B17<='Lease Comparison'!F7,IF(MOD(B17-1,'Lease Comparison'!F19)<'Lease Comparison'!F14*12,'Lease Comparison'!F13*(1+'Lease Comparison'!F16)^INT((B17-1)/12),0),0) -> 4800 | H17: =IF(B17<='Lease Comparison'!F7,1/(1+'Lease Comparison'!C8)^B17,0) -> 0.92592593 | I17: =G17*H17 -> 4444.4444
B18: 13 | C18: =IF(B18<='Lease Comparison'!F7,IF(MOD(B18-1,'Lease Comparison'!C19)<'Lease Comparison'!C14*12,'Lease Comparison'!C13*(1+'Lease Comparison'!C16)^INT((B18-1)/12),0),0) -> 0 | D18: =IF(B18<='Lease Comparison'!F7,1/(1+'Lease Comparison'!C8)^B18,0) -> 0.92000658 | E18: =C18*D18 -> 0 | G18: =IF(B18<='Lease Comparison'!F7,IF(MOD(B18-1,'Lease Comparison'!F19)<'Lease Comparison'!F14*12,'Lease Comparison'!F13*(1+'Lease Comparison'!F16)^INT((B18-1)/12),0),0) -> 4944 | H18: =IF(B18<='Lease Comparison'!F7,1/(1+'Lease Comparison'!C8)^B18,0) -> 0.92000658 | I18: =G18*H18 -> 4548.5125
B19: 14 | C19: =IF(B19<='Lease Comparison'!F7,IF(MOD(B19-1,'Lease Comparison'!C19)<'Lease Comparison'!C14*12,'Lease Comparison'!C13*(1+'Lease Comparison'!C16)^INT((B19-1)/12),0),0) -> 0 | D19: =IF(B19<='Lease Comparison'!F7,1/(1+'Lease Comparison'!C8)^B19,0) -> 0.91412507 | E19: =C19*D19 -> 0 | G19: =IF(B19<='Lease Comparison'!F7,IF(MOD(B19-1,'Lease Comparison'!F19)<'Lease Comparison'!F14*12,'Lease Comparison'!F13*(1+'Lease Comparison'!F16)^INT((B19-1)/12),0),0) -> 4944 | H19: =IF(B19<='Lease Comparison'!F7,1/(1+'Lease Comparison'!C8)^B19,0) -> 0.91412507 | I19: =G19*H19 -> 4519.4343
B20: 15 | C20: =IF(B20<='Lease Comparison'!F7,IF(MOD(B20-1,'Lease Comparison'!C19)<'Lease Comparison'!C14*12,'Lease Comparison'!C13*(1+'Lease Comparison'!C16)^INT((B20-1)/12),0),0) -> 0 | D20: =IF(B20<='Lease Comparison'!F7,1/(1+'Lease Comparison'!C8)^B20,0) -> 0.90828116 | E20: =C20*D20 -> 0 | G20: =IF(B20<='Lease Comparison'!F7,IF(MOD(B20-1,'Lease Comparison'!F19)<'Lease Comparison'!F14*12,'Lease Comparison'!F13*(1+'Lease Comparison'!F16)^INT((B20-1)/12),0),0) -> 4944 | H20: =IF(B20<='Lease Comparison'!F7,1/(1+'Lease Comparison'!C8)^B20,0) -> 0.90828116 | I20: =G20*H20 -> 4490.5421
B21: 16 | C21: =IF(B21<='Lease Comparison'!F7,IF(MOD(B21-1,'Lease Comparison'!C19)<'Lease Comparison'!C14*12,'Lease Comparison'!C13*(1+'Lease Comparison'!C16)^INT((B21-1)/12),0),0) -> 4635 | D21: =IF(B21<='Lease Comparison'!F7,1/(1+'Lease Comparison'!C8)^B21,0) -> 0.90247461 | E21: =C21*D21 -> 4182.9698 | G21: =IF(B21<='Lease Comparison'!F7,IF(MOD(B21-1,'Lease Comparison'!F19)<'Lease Comparison'!F14*12,'Lease Comparison'!F13*(1+'Lease Comparison'!F16)^INT((B21-1)/12),0),0) -> 4944 | H21: =IF(B21<='Lease Comparison'!F7,1/(1+'Lease Comparison'!C8)^B21,0) -> 0.90247461 | I21: =G21*H21 -> 4461.8345
B22: 17 | C22: =IF(B22<='Lease Comparison'!F7,IF(MOD(B22-1,'Lease Comparison'!C19)<'Lease Comparison'!C14*12,'Lease Comparison'!C13*(1+'Lease Comparison'!C16)^INT((B22-1)/12),0),0) -> 4635 | D22: =IF(B22<='Lease Comparison'!F7,1/(1+'Lease Comparison'!C8)^B22,0) -> 0.89670518 | E22: =C22*D22 -> 4156.2285 | G22: =IF(B22<='Lease Comparison'!F7,IF(MOD(B22-1,'Lease Comparison'!F19)<'Lease Comparison'!F14*12,'Lease Comparison'!F13*(1+'Lease Comparison'!F16)^INT((B22-1)/12),0),0) -> 4944 | H22: =IF(B22<='Lease Comparison'!F7,1/(1+'Lease Comparison'!C8)^B22,0) -> 0.89670518 | I22: =G22*H22 -> 4433.3104
B23: 18 | C23: =IF(B23<='Lease Comparison'!F7,IF(MOD(B23-1,'Lease Comparison'!C19)<'Lease Comparison'!C14*12,'Lease Comparison'!C13*(1+'Lease Comparison'!C16)^INT((B23-1)/12),0),0) -> 4635 | D23: =IF(B23<='Lease Comparison'!F7,1/(1+'Lease Comparison'!C8)^B23,0) -> 0.89097264 | E23: =C23*D23 -> 4129.6582 | G23: =IF(B23<='Lease Comparison'!F7,IF(MOD(B23-1,'Lease Comparison'!F19)<'Lease Comparison'!F14*12,'Lease Comparison'!F13*(1+'Lease Comparison'!F16)^INT((B23-1)/12),0),0) -> 4944 | H23: =IF(B23<='Lease Comparison'!F7,1/(1+'Lease Comparison'!C8)^B23,0) -> 0.89097264 | I23: =G23*H23 -> 4404.9687
B24: 19 | C24: =IF(B24<='Lease Comparison'!F7,IF(MOD(B24-1,'Lease Comparison'!C19)<'Lease Comparison'!C14*12,'Lease Comparison'!C13*(1+'Lease Comparison'!C16)^INT((B24-1)/12),0),0) -> 4635 | D24: =IF(B24<='Lease Comparison'!F7,1/(1+'Lease Comparison'!C8)^B24,0) -> 0.88527674 | E24: =C24*D24 -> 4103.2577 | G24: =IF(B24<='Lease Comparison'!F7,IF(MOD(B24-1,'Lease Comparison'!F19)<'Lease Comparison'!F14*12,'Lease Comparison'!F13*(1+'Lease Comparison'!F16)^INT((B24-1)/12),0),0) -> 4944 | H24: =IF(B24<='Lease Comparison'!F7,1/(1+'Lease Comparison'!C8)^B24,0) -> 0.88527674 | I24: =G24*H24 -> 4376.8082
B25: 20 | C25: =IF(B25<='Lease Comparison'!F7,IF(MOD(B25-1,'Lease Comparison'!C19)<'Lease Comparison'!C14*12,'Lease Comparison'!C13*(1+'Lease Comparison'!C16)^INT((B25-1)/12),0),0) -> 4635 | D25: =IF(B25<='Lease Comparison'!F7,1/(1+'Lease Comparison'!C8)^B25,0) -> 0.87961726 | E25: =C25*D25 -> 4077.026 | G25: =IF(B25<='Lease Comparison'!F7,IF(MOD(B25-1,'Lease Comparison'!F19)<'Lease Comparison'!F14*12,'Lease Comparison'!F13*(1+'Lease Comparison'!F16)^INT((B25-1)/12),0),0) -> 4944 | H25: =IF(B25<='Lease Comparison'!F7,1/(1+'Lease Comparison'!C8)^B25,0) -> 0.87961726 | I25: =G25*H25 -> 4348.8277
B26: 21 | C26: =IF(B26<='Lease Comparison'!F7,IF(MOD(B26-1,'Lease Comparison'!C19)<'Lease Comparison'!C14*12,'Lease Comparison'!C13*(1+'Lease Comparison'!C16)^INT((B26-1)/12),0),0) -> 4635 | D26: =IF(B26<='Lease Comparison'!F7,1/(1+'Lease Comparison'!C8)^B26,0) -> 0.87399395 | E26: =C26*D26 -> 4050.962 | G26: =IF(B26<='Lease Comparison'!F7,IF(MOD(B26-1,'Lease Comparison'!F19)<'Lease Comparison'!F14*12,'Lease Comparison'!F13*(1+'Lease Comparison'!F16)^INT((B26-1)/12),0),0) -> 4944 | H26: =IF(B26<='Lease Comparison'!F7,1/(1+'Lease Comparison'!C8)^B26,0) -> 0.87399395 | I26: =G26*H26 -> 4321.0261
B27: 22 | C27: =IF(B27<='Lease Comparison'!F7,IF(MOD(B27-1,'Lease Comparison'!C19)<'Lease Comparison'!C14*12,'Lease Comparison'!C13*(1+'Lease Comparison'!C16)^INT((B27-1)/12),0),0) -> 4635 | D27: =IF(B27<='Lease Comparison'!F7,1/(1+'Lease Comparison'!C8)^B27,0) -> 0.8684066 | E27: =C27*D27 -> 4025.0646 | G27: =IF(B27<='Lease Comparison'!F7,IF(MOD(B27-1,'Lease Comparison'!F19)<'Lease Comparison'!F14*12,'Lease Comparison'!F13*(1+'Lease Comparison'!F16)^INT((B27-1)/12),0),0) -> 4944 | H27: =IF(B27<='Lease Comparison'!F7,1/(1+'Lease Comparison'!C8)^B27,0) -> 0.8684066 | I27: =G27*H27 -> 4293.4022
B28: 23 | C28: =IF(B28<='Lease Comparison'!F7,IF(MOD(B28-1,'Lease Comparison'!C19)<'Lease Comparison'!C14*12,'Lease Comparison'!C13*(1+'Lease Comparison'!C16)^INT((B28-1)/12),0),0) -> 4635 | D28: =IF(B28<='Lease Comparison'!F7,1/(1+'Lease Comparison'!C8)^B28,0) -> 0.86285496 | E28: =C28*D28 -> 3999.3328 | G28: =IF(B28<='Lease Comparison'!F7,IF(MOD(B28-1,'Lease Comparison'!F19)<'Lease Comparison'!F14*12,'Lease Comparison'!F13*(1+'Lease Comparison'!F16)^INT((B28-1)/12),0),0) -> 4944 | H28: =IF(B28<='Lease Comparison'!F7,1/(1+'Lease Comparison'!C8)^B28,0) -> 0.86285496 | I28: =G28*H28 -> 4265.9549
B29: 24 | C29: =IF(B29<='Lease Comparison'!F7,IF(MOD(B29-1,'Lease Comparison'!C19)<'Lease Comparison'!C14*12,'Lease Comparison'!C13*(1+'Lease Comparison'!C16)^INT((B29-1)/12),0),0) -> 4635 | D29: =IF(B29<='Lease Comparison'!F7,1/(1+'Lease Comparison'!C8)^B29,0) -> 0.85733882 | E29: =C29*D29 -> 3973.7654 | G29: =IF(B29<='Lease Comparison'!F7,IF(MOD(B29-1,'Lease Comparison'!F19)<'Lease Comparison'!F14*12,'Lease Comparison'!F13*(1+'Lease Comparison'!F16)^INT((B29-1)/12),0),0) -> 4944 | H29: =IF(B29<='Lease Comparison'!F7,1/(1+'Lease Comparison'!C8)^B29,0) -> 0.85733882 | I29: =G29*H29 -> 4238.6831
B30: 25 | C30: =IF(B30<='Lease Comparison'!F7,IF(MOD(B30-1,'Lease Comparison'!C19)<'Lease Comparison'!C14*12,'Lease Comparison'!C13*(1+'Lease Comparison'!C16)^INT((B30-1)/12),0),0) -> 4774.05 | D30: =IF(B30<='Lease Comparison'!F7,1/(1+'Lease Comparison'!C8)^B30,0) -> 0.85185794 | E30: =C30*D30 -> 4066.8124 | G30: =IF(B30<='Lease Comparison'!F7,IF(MOD(B30-1,'Lease Comparison'!F19)<'Lease Comparison'!F14*12,'Lease Comparison'!F13*(1+'Lease Comparison'!F16)^INT((B30-1)/12),0),0) -> 5092.32 | H30: =IF(B30<='Lease Comparison'!F7,1/(1+'Lease Comparison'!C8)^B30,0) -> 0.85185794 | I30: =G30*H30 -> 4337.9332
B31: 26 | C31: =IF(B31<='Lease Comparison'!F7,IF(MOD(B31-1,'Lease Comparison'!C19)<'Lease Comparison'!C14*12,'Lease Comparison'!C13*(1+'Lease Comparison'!C16)^INT((B31-1)/12),0),0) -> 4774.05 | D31: =IF(B31<='Lease Comparison'!F7,1/(1+'Lease Comparison'!C8)^B31,0) -> 0.8464121 | E31: =C31*D31 -> 4040.8137 | G31: =IF(B31<='Lease Comparison'!F7,IF(MOD(B31-1,'Lease Comparison'!F19)<'Lease Comparison'!F14*12,'Lease Comparison'!F13*(1+'Lease Comparison'!F16)^INT((B31-1)/12),0),0) -> 5092.32 | H31: =IF(B31<='Lease Comparison'!F7,1/(1+'Lease Comparison'!C8)^B31,0) -> 0.8464121 | I31: =G31*H31 -> 4310.2013
B32: 27 | C32: =IF(B32<='Lease Comparison'!F7,IF(MOD(B32-1,'Lease Comparison'!C19)<'Lease Comparison'!C14*12,'Lease Comparison'!C13*(1+'Lease Comparison'!C16)^INT((B32-1)/12),0),0) -> 4774.05 | D32: =IF(B32<='Lease Comparison'!F7,1/(1+'Lease Comparison'!C8)^B32,0) -> 0.84100107 | E32: =C32*D32 -> 4014.9812 | G32: =IF(B32<='Lease Comparison'!F7,IF(MOD(B32-1,'Lease Comparison'!F19)<'Lease Comparison'!F14*12,'Lease Comparison'!F13*(1+'Lease Comparison'!F16)^INT((B32-1)/12),0),0) -> 5092.32 | H32: =IF(B32<='Lease Comparison'!F7,1/(1+'Lease Comparison'!C8)^B32,0) -> 0.84100107 | I32: =G32*H32 -> 4282.6466
B33: 28 | C33: =IF(B33<='Lease Comparison'!F7,IF(MOD(B33-1,'Lease Comparison'!C19)<'Lease Comparison'!C14*12,'Lease Comparison'!C13*(1+'Lease Comparison'!C16)^INT((B33-1)/12),0),0) -> 0 | D33: =IF(B33<='Lease Comparison'!F7,1/(1+'Lease Comparison'!C8)^B33,0) -> 0.83562464 | E33: =C33*D33 -> 0 | G33: =IF(B33<='Lease Comparison'!F7,IF(MOD(B33-1,'Lease Comparison'!F19)<'Lease Comparison'!F14*12,'Lease Comparison'!F13*(1+'Lease Comparison'!F16)^INT((B33-1)/12),0),0) -> 5092.32 | H33: =IF(B33<='Lease Comparison'!F7,1/(1+'Lease Comparison'!C8)^B33,0) -> 0.83562464 | I33: =G33*H33 -> 4255.2681
B34: 29 | C34: =IF(B34<='Lease Comparison'!F7,IF(MOD(B34-1,'Lease Comparison'!C19)<'Lease Comparison'!C14*12,'Lease Comparison'!C13*(1+'Lease Comparison'!C16)^INT((B34-1)/12),0),0) -> 0 | D34: =IF(B34<='Lease Comparison'!F7,1/(1+'Lease Comparison'!C8)^B34,0) -> 0.83028258 | E34: =C34*D34 -> 0 | G34: =IF(B34<='Lease Comparison'!F7,IF(MOD(B34-1,'Lease Comparison'!F19)<'Lease Comparison'!F14*12,'Lease Comparison'!F13*(1+'Lease Comparison'!F16)^INT((B34-1)/12),0),0) -> 5092.32 | H34: =IF(B34<='Lease Comparison'!F7,1/(1+'Lease Comparison'!C8)^B34,0) -> 0.83028258 | I34: =G34*H34 -> 4228.0646
B35: 30 | C35: =IF(B35<='Lease Comparison'!F7,IF(MOD(B35-1,'Lease Comparison'!C19)<'Lease Comparison'!C14*12,'Lease Comparison'!C13*(1+'Lease Comparison'!C16)^INT((B35-1)/12),0),0) -> 0 | D35: =IF(B35<='Lease Comparison'!F7,1/(1+'Lease Comparison'!C8)^B35,0) -> 0.82497466 | E35: =C35*D35 -> 0 | G35: =IF(B35<='Lease Comparison'!F7,IF(MOD(B35-1,'Lease Comparison'!F19)<'Lease Comparison'!F14*12,'Lease Comparison'!F13*(1+'Lease Comparison'!F16)^INT((B35-1)/12),0),0) -> 5092.32 | H35: =IF(B35<='Lease Comparison'!F7,1/(1+'Lease Comparison'!C8)^B35,0) -> 0.82497466 | I35: =G35*H35 -> 4201.035
B36: 31 | C36: =IF(B36<='Lease Comparison'!F7,IF(MOD(B36-1,'Lease Comparison'!C19)<'Lease Comparison'!C14*12,'Lease Comparison'!C13*(1+'Lease Comparison'!C16)^INT((B36-1)/12),0),0) -> 4774.05 | D36: =IF(B36<='Lease Comparison'!F7,1/(1+'Lease Comparison'!C8)^B36,0) -> 0.81970069 | E36: =C36*D36 -> 3913.2921 | G36: =IF(B36<='Lease Comparison'!F7,IF(MOD(B36-1,'Lease Comparison'!F19)<'Lease Comparison'!F14*12,'Lease Comparison'!F13*(1+'Lease Comparison'!F16)^INT((B36-1)/12),0),0) -> 5092.32 | H36: =IF(B36<='Lease Comparison'!F7,1/(1+'Lease Comparison'!C8)^B36,0) -> 0.81970069 | I36: =G36*H36 -> 4174.1782
B37: 32 | C37: =IF(B37<='Lease Comparison'!F7,IF(MOD(B37-1,'Lease Comparison'!C19)<'Lease Comparison'!C14*12,'Lease Comparison'!C13*(1+'Lease Comparison'!C16)^INT((B37-1)/12),0),0) -> 4774.05 | D37: =IF(B37<='Lease Comparison'!F7,1/(1+'Lease Comparison'!C8)^B37,0) -> 0.81446042 | E37: =C37*D37 -> 3888.2748 | G37: =IF(B37<='Lease Comparison'!F7,IF(MOD(B37-1,'Lease Comparison'!F19)<'Lease Comparison'!F14*12,'Lease Comparison'!F13*(1+'Lease Comparison'!F16)^INT((B37-1)/12),0),0) -> 5092.32 | H37: =IF(B37<='Lease Comparison'!F7,1/(1+'Lease Comparison'!C8)^B37,0) -> 0.81446042 | I37: =G37*H37 -> 4147.4931
B38: 33 | C38: =IF(B38<='Lease Comparison'!F7,IF(MOD(B38-1,'Lease Comparison'!C19)<'Lease Comparison'!C14*12,'Lease Comparison'!C13*(1+'Lease Comparison'!C16)^INT((B38-1)/12),0),0) -> 4774.05 | D38: =IF(B38<='Lease Comparison'!F7,1/(1+'Lease Comparison'!C8)^B38,0) -> 0.80925366 | E38: =C38*D38 -> 3863.4174 | G38: =IF(B38<='Lease Comparison'!F7,IF(MOD(B38-1,'Lease Comparison'!F19)<'Lease Comparison'!F14*12,'Lease Comparison'!F13*(1+'Lease Comparison'!F16)^INT((B38-1)/12),0),0) -> 5092.32 | H38: =IF(B38<='Lease Comparison'!F7,1/(1+'Lease Comparison'!C8)^B38,0) -> 0.80925366 | I38: =G38*H38 -> 4120.9786
B39: 34 | C39: =IF(B39<='Lease Comparison'!F7,IF(MOD(B39-1,'Lease Comparison'!C19)<'Lease Comparison'!C14*12,'Lease Comparison'!C13*(1+'Lease Comparison'!C16)^INT((B39-1)/12),0),0) -> 4774.05 | D39: =IF(B39<='Lease Comparison'!F7,1/(1+'Lease Comparison'!C8)^B39,0) -> 0.80408018 | E39: =C39*D39 -> 3838.719 | G39: =IF(B39<='Lease Comparison'!F7,IF(MOD(B39-1,'Lease Comparison'!F19)<'Lease Comparison'!F14*12,'Lease Comparison'!F13*(1+'Lease Comparison'!F16)^INT((B39-1)/12),0),0) -> 5092.32 | H39: =IF(B39<='Lease Comparison'!F7,1/(1+'Lease Comparison'!C8)^B39,0) -> 0.80408018 | I39: =G39*H39 -> 4094.6336
B40: 35 | C40: =IF(B40<='Lease Comparison'!F7,IF(MOD(B40-1,'Lease Comparison'!C19)<'Lease Comparison'!C14*12,'Lease Comparison'!C13*(1+'Lease Comparison'!C16)^INT((B40-1)/12),0),0) -> 4774.05 | D40: =IF(B40<='Lease Comparison'!F7,1/(1+'Lease Comparison'!C8)^B40,0) -> 0.79893978 | E40: =C40*D40 -> 3814.1785 | G40: =IF(B40<='Lease Comparison'!F7,IF(MOD(B40-1,'Lease Comparison'!F19)<'Lease Comparison'!F14*12,'Lease Comparison'!F13*(1+'Lease Comparison'!F16)^INT((B40-1)/12),0),0) -> 5092.32 | H40: =IF(B40<='Lease Comparison'!F7,1/(1+'Lease Comparison'!C8)^B40,0) -> 0.79893978 | I40: =G40*H40 -> 4068.457
B41: 36 | C41: =IF(B41<='Lease Comparison'!F7,IF(MOD(B41-1,'Lease Comparison'!C19)<'Lease Comparison'!C14*12,'Lease Comparison'!C13*(1+'Lease Comparison'!C16)^INT((B41-1)/12),0),0) -> 4774.05 | D41: =IF(B41<='Lease Comparison'!F7,1/(1+'Lease Comparison'!C8)^B41,0) -> 0.79383224 | E41: =C41*D41 -> 3789.7948 | G41: =IF(B41<='Lease Comparison'!F7,IF(MOD(B41-1,'Lease Comparison'!F19)<'Lease Comparison'!F14*12,'Lease Comparison'!F13*(1+'Lease Comparison'!F16)^INT((B41-1)/12),0),0) -> 5092.32 | H41: =IF(B41<='Lease Comparison'!F7,1/(1+'Lease Comparison'!C8)^B41,0) -> 0.79383224 | I41: =G41*H41 -> 4042.4478
B42: 37 | C42: =IF(B42<='Lease Comparison'!F7,IF(MOD(B42-1,'Lease Comparison'!C19)<'Lease Comparison'!C14*12,'Lease Comparison'!C13*(1+'Lease Comparison'!C16)^INT((B42-1)/12),0),0) -> 4917.2715 | D42: =IF(B42<='Lease Comparison'!F7,1/(1+'Lease Comparison'!C8)^B42,0) -> 0.78875735 | E42: =C42*D42 -> 3878.534 | G42: =IF(B42<='Lease Comparison'!F7,IF(MOD(B42-1,'Lease Comparison'!F19)<'Lease Comparison'!F14*12,'Lease Comparison'!F13*(1+'Lease Comparison'!F16)^INT((B42-1)/12),0),0) -> 5245.0896 | H42: =IF(B42<='Lease Comparison'!F7,1/(1+'Lease Comparison'!C8)^B42,0) -> 0.78875735 | I42: =G42*H42 -> 4137.103
...
