Workbook

Sheet Scenario A - Full Sidewalk
A1: 34 Plaza Owners Corp.
A2: Updated Capital Plan — Full Replacement ($230K)
A3: Prepared for Board Meeting — March 2026
A5: KEY ASSUMPTIONS
A6: Starting Reserve Balance (Audited 12/31/2025): | B6: 1141745 | C6: Source: Draft Audited Financial Statements
A7: Annual Capital Contribution (2026): | B7: 262500
A8: Capital Contribution Annual Growth Rate: | B8: 0.05
A9: Remaining Capital Assessment (2025 assessment tail): | B9: 187217
A10: Annual General Capital Maintenance Allowance: | B10: 150000 | C10: Based on 2023 actuals (~$131K) + inflation buffer
A11: Mortgage Maturity (3.225% interest-only, $5.618M): | B11: 12/1/2028 | C11: KEY RISK — Refinancing required
A13: UPCOMING PROJECTS | B13: 2026 | C13: 2027 | D13: 2028 | E13: 2029 | F13: 2030
A14: FISP/Local Law 11 — SAFE Filing | B14: 25000
A15: Sidewalks & Landscaping | B15: 230000
A16: Professional Space Buildout | B16: 25000
A17: Balance from Garage | B17: 44000
A18: Elevator | C18: 700000 | D18: 300000
A19: G Level | F19: 100000
A20: Lobby HVAC | E20: 50000
A21: Lobby Renovation | E21: 150000
A22: FISP/Local Law 11 — Major Facade Work | F22: Est. 2031-2032
A23: General Capital Maintenance | B23: =$B$10 -> 150000 | C23: =$B$10 -> 150000 | D23: =$B$10 -> 150000 | E23: =$B$10 -> 150000 | F23: =$B$10 -> 150000
A24: TOTAL PROJECTS | B24: =SUM(B14:B23) -> 474000 | C24: =SUM(C14:C23) -> 850000 | D24: =SUM(D14:D23) -> 450000 | E24: =SUM(E14:E23) -> 350000 | F24: =SUM(F14:F23) -> 250000
A26: RESERVE CASH FLOW
A27: Beginning Reserve Cash | B27: =B6 -> 1141745 | C27: =B33 -> 1117462 | D27: =C33 -> 574405 | E27: =D33 -> 414983.25 | F27: =E33 -> 368859.81
A28: Capital Assessment Income | B28: 187217 | C28: 31318 | D28: 1172 | E28: 0 | F28: 0
A29: Capital Contribution | B29: =B7 -> 262500 | C29: =B29*(1+$B$8) -> 275625 | D29: =C29*(1+$B$8) -> 289406.25 | E29: =D29*(1+$B$8) -> 303876.56 | F29: =E29*(1+$B$8) -> 319070.39
A30: Total Inflows | B30: =B28+B29 -> 449717 | C30: =C28+C29 -> 306943 | D30: =D28+D29 -> 290578.25 | E30: =E28+E29 -> 303876.56 | F30: =F28+F29 -> 319070.39
A31: Less: Project Spending | B31: =-B24 -> -474000 | C31: =-C24 -> -850000 | D31: =-D24 -> -450000 | E31: =-E24 -> -350000 | F31: =-F24 -> -250000
A32: Net Change in Reserves | B32: =B30+B31 -> -24283 | C32: =C30+C31 -> -543057 | D32: =D30+D31 -> -159421.75 | E32: =E30+E31 -> -46123.438 | F32: =F30+F31 -> 69070.391
A33: Ending Reserve Cash, Projected | B33: =B27+B32 -> 1117462 | C33: =C27+C32 -> 574405 | D33: =D27+D32 -> 414983.25 | E33: =E27+E32 -> 368859.81 | F33: =F27+F32 -> 437930.2
A35: Three Months Maintenance (benchmark): | B35: 562862 | C35: =B35*(1+$B$8) -> 591005.1 | D35: =C35*(1+$B$8) -> 620555.35 | E35: =D35*(1+$B$8) -> 651583.12 | F35: =E35*(1+$B$8) -> 684162.28
A36: Reserve as % of 3-Month Maintenance: | B36: =IF(B35=0,0,B33/B35) -> 1.9853214 | C36: =IF(C35=0,0,C33/C35) -> 0.97191209 | D36: =IF(D35=0,0,D33/D35) -> 0.66872882 | E36: =IF(E35=0,0,E33/E35) -> 0.56609786 | F36: =IF(F35=0,0,F33/F35) -> 0.64009697
A38: NOTES
A39: 1. Garage SREM LL126 ($196,494) was paid in 2025 — removed from 2026 plan.
A40: 2. Sidewalks: Full Replacement ($230K) option (was $300,000 in prior plan).
A41: 3. FISP: $25K SAFE filing in 2026; major facade work deferred to next cycle (est. 2031-2032).
A42: 4. Professional space buildout of $25K added for 2026.
A43: 5. General Capital Maintenance of $150K/yr based on 2023 actuals (~$131K) + inflation buffer.
A44: 6. Mortgage ($5.618M at 3.225%) matures 12/1/2028 — refinancing will impact cash flow.
A45: 7. Capital contribution assumes 5% annual growth (yellow-highlighted assumption).
...

Sheet Scenario B - Targeted Repair
A1: 34 Plaza Owners Corp.
A2: Updated Capital Plan — Targeted Tile Repair ($30K)
A3: Prepared for Board Meeting — March 2026
A5: KEY ASSUMPTIONS
A6: Starting Reserve Balance (Audited 12/31/2025): | B6: 1141745 | C6: Source: Draft Audited Financial Statements
A7: Annual Capital Contribution (2026): | B7: 262500
A8: Capital Contribution Annual Growth Rate: | B8: 0.05
A9: Remaining Capital Assessment (2025 assessment tail): | B9: 187217
A10: Annual General Capital Maintenance Allowance: | B10: 150000 | C10: Based on 2023 actuals (~$131K) + inflation buffer
A11: Mortgage Maturity (3.225% interest-only, $5.618M): | B11: 12/1/2028 | C11: KEY RISK — Refinancing required
A13: UPCOMING PROJECTS | B13: 2026 | C13: 2027 | D13: 2028 | E13: 2029 | F13: 2030
A14: FISP/Local Law 11 — SAFE Filing | B14: 25000
A15: Sidewalks & Landscaping | B15: 35000
A16: Professional Space Buildout | B16: 25000
A17: Balance From Garage | B17: 44000
A18: Local Law 11 Proposal | F18: 12976
A19: Elevator | B19: 500000 | C19: 500000
A20: G Level | F20: 100000
A21: Lobby HVAC | E21: 50000
A22: Lobby Renovation | E22: 150000
A23: FISP/Local Law 11 — Major Facade Work | F23: Est. 2031-2032
A24: General Capital Maintenance | B24: =B10/2 -> 75000 | C24: =$B$10 -> 150000 | D24: =$B$10 -> 150000 | E24: =$B$10 -> 150000 | F24: =$B$10 -> 150000
A25: TOTAL PROJECTS | B25: =SUM(B14:B24) -> 704000 | C25: =SUM(C14:C24) -> 650000 | D25: =SUM(D14:D24) -> 150000 | E25: =SUM(E14:E24) -> 350000 | F25: =SUM(F14:F24) -> 262976
A27: RESERVE CASH FLOW
A28: Beginning Reserve Cash | B28: =B6 -> 1141745 | C28: =B34 -> 887462 | D28: =C34 -> 544405 | E28: =D34 -> 684983.25 | F28: =E34 -> 638859.81
A29: Capital Assessment Income | B29: 187217 | C29: 31318 | D29: 1172 | E29: 0 | F29: 0
A30: Capital Contribution | B30: =B7 -> 262500 | C30: =B30*(1+$B$8) -> 275625 | D30: =C30*(1+$B$8) -> 289406.25 | E30: =D30*(1+$B$8) -> 303876.56 | F30: =E30*(1+$B$8) -> 319070.39
A31: Total Inflows | B31: =B29+B30 -> 449717 | C31: =C29+C30 -> 306943 | D31: =D29+D30 -> 290578.25 | E31: =E29+E30 -> 303876.56 | F31: =F29+F30 -> 319070.39
A32: Less: Project Spending | B32: =-B25 -> -704000 | C32: =-C25 -> -650000 | D32: =-D25 -> -150000 | E32: =-E25 -> -350000 | F32: =-F25 -> -262976
A33: Net Change in Reserves | B33: =B31+B32 -> -254283 | C33: =C31+C32 -> -343057 | D33: =D31+D32 -> 140578.25 | E33: =E31+E32 -> -46123.438 | F33: =F31+F32 -> 56094.391
A34: Ending Reserve Cash, Projected | B34: =B28+B33 -> 887462 | C34: =C28+C33 -> 544405 | D34: =D28+D33 -> 684983.25 | E34: =E28+E33 -> 638859.81 | F34: =F28+F33 -> 694954.2
A36: Three Months Maintenance (benchmark): | B36: 562862 | C36: =B36*(1+$B$8) -> 591005.1 | D36: =C36*(1+$B$8) -> 620555.35 | E36: =D36*(1+$B$8) -> 651583.12 | F36: =E36*(1+$B$8) -> 684162.28
A37: Reserve as % of 3-Month Maintenance: | B37: =IF(B36=0,0,B34/B36) -> 1.5766955 | C37: =IF(C36=0,0,C34/C36) -> 0.9211511 | D37: =IF(D36=0,0,D34/D36) -> 1.103823 | E37: =IF(E36=0,0,E34/E36) -> 0.98047324 | F37: =IF(F36=0,0,F34/F36) -> 1.0157739
A39: NOTES
A40: 1. Garage SREM LL126 ($196,494) was paid in 2025 — removed from 2026 plan.
A41: 2. Sidewalks: Targeted Tile Repair ($30K) option (was $300,000 in prior plan).
A42: 3. FISP: $25K SAFE filing in 2026; major facade work deferred to next cycle (est. 2031-2032).
A43: 4. Professional space buildout of $25K added for 2026.
A44: 5. General Capital Maintenance of $150K/yr based on 2023 actuals (~$131K) + inflation buffer.
A45: 6. Mortgage ($5.618M at 3.225%) matures 12/1/2028 — refinancing will impact cash flow.
...

Sheet Scenario Comparison
A1: 34 Plaza Owners Corp.
A2: Capital Plan — Scenario Comparison
B4: 2026 | C4: 2027 | D4: 2028 | E4: 2029 | F4: 2030
A5: Scenario A — Ending Reserve (Full $230K) | B5: ='Scenario A - Full Sidewalk'!B33 -> 1117462 | C5: ='Scenario A - Full Sidewalk'!C33 -> 574405 | D5: ='Scenario A - Full Sidewalk'!D33 -> 414983.25 | E5: ='Scenario A - Full Sidewalk'!E33 -> 368859.81 | F5: ='Scenario A - Full Sidewalk'!F33 -> 437930.2
A6: Scenario B — Ending Reserve (Targeted $30K) | B6: ='Scenario B - Targeted Repair'!B34 -> 887462 | C6: ='Scenario B - Targeted Repair'!C34 -> 544405 | D6: ='Scenario B - Targeted Repair'!D34 -> 684983.25 | E6: ='Scenario B - Targeted Repair'!E34 -> 638859.81 | F6: ='Scenario B - Targeted Repair'!F34 -> 694954.2
A7: Difference (B minus A) | B7: =B6-B5 -> -230000 | C7: =C6-C5 -> -30000 | D7: =D6-D5 -> 270000 | E7: =E6-E5 -> 270000 | F7: =F6-F5 -> 257024
A9: The targeted repair option preserves $200,000 more in reserves through the full projection period.
A10: However, full sidewalk replacement eliminates the recurring maintenance liability.
A12: RESERVE ADEQUACY CHECK
A13: Scenario A — Reserve as % of 3-Mo Maint. | B13: ='Scenario A - Full Sidewalk'!B36 -> 1.9853214 | C13: ='Scenario A - Full Sidewalk'!C36 -> 0.97191209 | D13: ='Scenario A - Full Sidewalk'!D36 -> 0.66872882 | E13: ='Scenario A - Full Sidewalk'!E36 -> 0.56609786 | F13: ='Scenario A - Full Sidewalk'!F36 -> 0.64009697
A14: Scenario B — Reserve as % of 3-Mo Maint. | B14: ='Scenario B - Targeted Repair'!B37 -> 1.5766955 | C14: ='Scenario B - Targeted Repair'!C37 -> 0.9211511 | D14: ='Scenario B - Targeted Repair'!D37 -> 1.103823 | E14: ='Scenario B - Targeted Repair'!E37 -> 0.98047324 | F14: ='Scenario B - Targeted Repair'!F37 -> 1.0157739
A16: NOTE: Both scenarios include $150K/yr general capital maintenance allocation (elevator repairs, plumbing, doors/windows, etc.)
